<mujoco model="compound_joint">
  <!-- Two-link arm where the first link has TWO compound revolute joints on the same body.
       This configuration reproduces issue #1608: before the dof_offset fix, the second joint
       writes to the wrong Jacobian column, overwriting the first joint's entry. -->
  <compiler angle="radian"/>
  <option gravity="0 0 0"/>
  <worldbody>
    <body name="base" pos="0 0 0">
      <!-- seg1 carries TWO revolute joints (compound joints on the same body) -->
      <body name="seg1" pos="0 0 0">
        <joint name="j_x" axis="1 0 0" type="hinge"/>
        <joint name="j_y" axis="0 1 0" type="hinge"/>
        <geom type="capsule" fromto="0 0 0 0 0 0.4" size="0.02" rgba="1 0 0 1"/>
        <body name="seg2" pos="0 0 0.4">
          <joint name="j_z" axis="0 0 1" type="hinge"/>
          <geom type="capsule" fromto="0 0 0 0 0 0.4" size="0.02" rgba="0 1 0 1"/>
        </body>
      </body>
    </body>
  </worldbody>
</mujoco>
